Workbook

Sheet 00_Cover
B2: Northline Consumer Products
B3: Driver-based P&L forecast · volume × price · COGS drivers · OpEx by cost center
B4: FY2026 monthly · plan vs reforecast · fictional CPG company · $000s
B6: What this file is
B7: A twelve-month driver-based P&L for a fictional mid-size CPG company. Revenue is volume × net price by product line. COGS is volume × material / labor / overhead per case. OpEx is built by cost center (rate + monthly fixed). Plan and latest-view forecast live on Assumptions; the P&L and the plan-vs-forecast bridge are formulas. A scenario toggle (Base / Upside / Downside) scales forecast volume, price, unit cost, and discretionary OpEx.
B9: How to use
B10: 1. Edit yellow cells on 01_Assumptions (scenario, prices, unit costs, volumes, OpEx rates and monthly fixed).
B11: 2. Read volume × price and mix on 02_Revenue_Build (plan, scenario-applied forecast, variance).
B12: 3. Read unit-cost COGS and gross margin on 03_COGS_Build.
B13: 4. Read cost-center OpEx (selling, marketing, distribution, G&A, R&D) on 04_OpEx.
B14: 5. Read the 12-month P&L on 05_P&L_Forecast. Walk plan → forecast on 06_Bridge (volume / mix / price / cost / OpEx).
B16: File conventions
... B23: https://github.com/saisiri-bandaru

Sheet 01_Assumptions
B2: Assumptions
B3: Yellow + blue = inputs. Scenario, prices, unit costs, volumes, and OpEx rates drive every other tab.
B5: Control panel
B6: Scenario (1 = Base, 2 = Upside, 3 = Downside) | C6: 1 | D6: =INDEX({"Base","Upside","Downside"},1,C6) | E6: Scales the latest-view forecast only. Plan stays put.
B7: Volume factor (on forecast volume) | C7: =INDEX($D$15:$D$17,$C$6)
B8: Price factor (on forecast net $/case) | C8: =INDEX($E$15:$E$17,$C$6)
B9: Unit-cost factor (on forecast CPU) | C9: =INDEX($F$15:$F$17,$C$6)
B10: Discretionary OpEx factor (marketing + R&D fixed) | C10: =INDEX($G$15:$G$17,$C$6)
B12: Scenario table (inputs)
B13: # | C13: Name | D13: Volume | E13: Price | F13: Unit cost | G13: Disc. OpEx
B15: 1 | C15: Base | D15: 1 | E15: 1 | F15: 1 | G15: 1
B16: 2 | C16: Upside | D16: 1.045 | E16: 1.012 | F16: 0.985 | G16: 1.03
B17: 3 | C17: Downside | D17: 0.955 | E17: 0.988 | F17: 1.025 | G17: 0.97
B19: Other drivers
B20: Tax rate | C20: 0.25
B21: D&A % of sales | C21: 0.034
B22: Cost inflation (forecast vs plan CPU) | C22: 0.018 | D22: Applied before the scenario unit-cost factor. 1.8% commodity / conversion inflation in the sample.
B24: Product economics
B25: Product | C25: Plan net $/case | D25: Fcst net $/case | E25: Material $/case | F25: Labor $/case | G25: Overhead $/case | H25: Plan CPU | I25: Fcst CPU
B26: RTD Beverages | C26: 11.9 | D26: 11.75 | E26: 5.4 | F26: 1.05 | G26: 0.85 | H26: =E26+F26+G26 | I26: =H26*(1+$C$22)*$C$9
B27: Salty Snacks | C27: 14.2 | D27: 14.5 | E27: 6.2 | F27: 1.2 | G27: 0.95 | H27: =E27+F27+G27 | I27: =H27*(1+$C$22)*$C$9
B28: Household Care | C28: 16.5 | D28: 16.55 | E28: 7.4 | F28: 1.35 | G28: 1.1 | H28: =E28+F28+G28 | I28: =H28*(1+$C$22)*$C$9
B29: Personal Care | C29: 18.8 | D29: 19 | E29: 8.1 | F29: 1.5 | G29: 1.25 | H29: =E29+F29+G29 | I29: =H29*(1+$C$22)*$C$9
B31: OpEx rate drivers
B32: Driver | C32: Plan | D32: Forecast
B33: Selling commission % of sales | C33: 0.028 | D33: 0.028
B34: Marketing % of sales | C34: 0.046 | D34: 0.049
B35: Distribution $ per case | C35: 0.68 | D35: 0.66
B37: Plan monthly fixed OpEx ($000s)
C38: Jan-26 | D38: Feb-26 | E38: Mar-26 | F38: Apr-26 | G38: May-26 | H38: Jun-26 | I38: Jul-26 | J38: Aug-26 | K38: Sep-26 | L38: Oct-26 | M38: Nov-26 | N38: Dec-26 | O38: FY26
B39: Selling | C39: 1100 | D39: 1100 | E39: 1100 | F39: 1100 | G39: 1100 | H39: 1100 | I39: 1100 | J39: 1100 | K39: 1100 | L39: 1100 | M39: 1100 | N39: 1100 | O39: =SUM(C39:N39)
B40: Marketing (campaigns) | C40: 900 | D40: 800 | E40: 1100 | F40: 1400 | G40: 1600 | H40: 1800 | I40: 1500 | J40: 1400 | K40: 1300 | L40: 2000 | M40: 2800 | N40: 3200 | O40: =SUM(C40:N40)
B41: Distribution | C41: 650 | D41: 650 | E41: 650 | F41: 650 | G41: 650 | H41: 650 | I41: 650 | J41: 650 | K41: 650 | L41: 650 | M41: 650 | N41: 650 | O41: =SUM(C41:N41)
B42: G&A | C42: 5100 | D42: 5100 | E42: 5100 | F42: 5100 | G42: 5100 | H42: 5100 | I42: 5100 | J42: 5100 | K42: 5100 | L42: 5100 | M42: 5100 | N42: 5100 | O42: =SUM(C42:N42)
B43: R&D | C43: 1550 | D43: 1550 | E43: 1550 | F43: 1550 | G43: 1550 | H43: 1550 | I43: 1550 | J43: 1550 | K43: 1550 | L43: 1550 | M43: 1550 | N43: 1550 | O43: =SUM(C43:N43)
B44: Total plan fixed OpEx | C44: =SUM(C39:C43) | D44: =SUM(D39:D43) | E44: =SUM(E39:E43) | F44: =SUM(F39:F43) | G44: =SUM(G39:G43) | H44: =SUM(H39:H43) | I44: =SUM(I39:I43) | J44: =SUM(J39:J43) | ... O44: =SUM(O39:O43)
B46: Forecast monthly fixed OpEx ($000s) — before discretionary factor on marketing + R&D
C47: Jan-26 | D47: Feb-26 | E47: Mar-26 | F47: Apr-26 | G47: May-26 | H47: Jun-26 | I47: Jul-26 | J47: Aug-26 | K47: Sep-26 | L47: Oct-26 | M47: Nov-26 | N47: Dec-26 | O47: FY26
B48: Selling | C48: 1100 | D48: 1100 | E48: 1100 | F48: 1100 | G48: 1100 | H48: 1100 | I48: 1100 | J48: 1100 | K48: 1100 | L48: 1100 | M48: 1100 | N48: 1100 | O48: =SUM(C48:N48)
B49: Marketing (campaigns) | C49: 920 | D49: 820 | E49: 1120 | F49: 1450 | G49: 1680 | H49: 1900 | I49: 1620 | J49: 1520 | K49: 1420 | L49: 2200 | M49: 3100 | N49: 3500 | O49: =SUM(C49:N49)
...

Sheet 02_Revenue_Build
B2: Revenue build — volume × net price
B3: Plan uses plan volume × plan price. Forecast uses latest-view volume × volume factor × forecast price × price factor.
B4: Scenario | C4: ='01_Assumptions'!D6
B6: PLAN
C7: Jan-26 | D7: Feb-26 | E7: Mar-26 | F7: Apr-26 | G7: May-26 | H7: Jun-26 | I7: Jul-26 | J7: Aug-26 | K7: Sep-26 | L7: Oct-26 | M7: Nov-26 | N7: Dec-26 | O7: FY26
B8: RTD Beverages volume | C8: ='01_Assumptions'!C57 | D8: ='01_Assumptions'!D57 | E8: ='01_Assumptions'!E57 | F8: ='01_Assumptions'!F57 | G8: ='01_Assumptions'!G57 | H8: ='01_Assumptions'!H57 | I8: ='01_Assumptions'!I57 | J8: ='01_Assumptions'!J57 | ... N8: ='01_Assumptions'!N57 | O8: =SUM(C8:N8)
B9: Salty Snacks volume | C9: ='01_Assumptions'!C58 | D9: ='01_Assumptions'!D58 | E9: ='01_Assumptions'!E58 | F9: ='01_Assumptions'!F58 | G9: ='01_Assumptions'!G58 | H9: ='01_Assumptions'!H58 | I9: ='01_Assumptions'!I58 | J9: ='01_Assumptions'!J58 | ... N9: ='01_Assumptions'!N58 | O9: =SUM(C9:N9)
B10: Household Care volume | C10: ='01_Assumptions'!C59 | D10: ='01_Assumptions'!D59 | E10: ='01_Assumptions'!E59 | F10: ='01_Assumptions'!F59 | G10: ='01_Assumptions'!G59 | H10: ='01_Assumptions'!H59 | I10: ='01_Assumptions'!I59 | J10: ='01_Assumptions'!J59 | ... N10: ='01_Assumptions'!N59 | O10: =SUM(C10:N10)
B11: Personal Care volume | C11: ='01_Assumptions'!C60 | D11: ='01_Assumptions'!D60 | E11: ='01_Assumptions'!E60 | F11: ='01_Assumptions'!F60 | G11: ='01_Assumptions'!G60 | H11: ='01_Assumptions'!H60 | I11: ='01_Assumptions'!I60 | J11: ='01_Assumptions'!J60 | ... N11: ='01_Assumptions'!N60 | O11: =SUM(C11:N11)
B12: Plan total volume | C12: =SUM(C8:C11) | D12: =SUM(D8:D11) | E12: =SUM(E8:E11) | F12: =SUM(F8:F11) | G12: =SUM(G8:G11) | H12: =SUM(H8:H11) | I12: =SUM(I8:I11) | J12: =SUM(J8:J11) | ... O12: =SUM(O8:O11)
B14: RTD Beverages net $/case | C14: ='01_Assumptions'!$C$26 | D14: ='01_Assumptions'!$C$26 | E14: ='01_Assumptions'!$C$26 | F14: ='01_Assumptions'!$C$26 | G14: ='01_Assumptions'!$C$26 | H14: ='01_Assumptions'!$C$26 | I14: ='01_Assumptions'!$C$26 | J14: ='01_Assumptions'!$C$26 | ... N14: ='01_Assumptions'!$C$26 | O14: =AVERAGE(C14:N14)
B15: Salty Snacks net $/case | C15: ='01_Assumptions'!$C$27 | D15: ='01_Assumptions'!$C$27 | E15: ='01_Assumptions'!$C$27 | F15: ='01_Assumptions'!$C$27 | G15: ='01_Assumptions'!$C$27 | H15: ='01_Assumptions'!$C$27 | I15: ='01_Assumptions'!$C$27 | J15: ='01_Assumptions'!$C$27 | ... N15: ='01_Assumptions'!$C$27 | O15: =AVERAGE(C15:N15)
B16: Household Care net $/case | C16: ='01_Assumptions'!$C$28 | D16: ='01_Assumptions'!$C$28 | E16: ='01_Assumptions'!$C$28 | F16: ='01_Assumptions'!$C$28 | G16: ='01_Assumptions'!$C$28 | H16: ='01_Assumptions'!$C$28 | I16: ='01_Assumptions'!$C$28 | J16: ='01_Assumptions'!$C$28 | ... N16: ='01_Assumptions'!$C$28 | O16: =AVERAGE(C16:N16)
B17: Personal Care net $/case | C17: ='01_Assumptions'!$C$29 | D17: ='01_Assumptions'!$C$29 | E17: ='01_Assumptions'!$C$29 | F17: ='01_Assumptions'!$C$29 | G17: ='01_Assumptions'!$C$29 | H17: ='01_Assumptions'!$C$29 | I17: ='01_Assumptions'!$C$29 | J17: ='01_Assumptions'!$C$29 | ... N17: ='01_Assumptions'!$C$29 | O17: =AVERAGE(C17:N17)
B19: RTD Beverages revenue | C19: =C8*C14 | D19: =D8*D14 | E19: =E8*E14 | F19: =F8*F14 | G19: =G8*G14 | H19: =H8*H14 | I19: =I8*I14 | J19: =J8*J14 | ... N19: =N8*N14 | O19: =SUM(C19:N19)
B20: Salty Snacks revenue | C20: =C9*C15 | D20: =D9*D15 | E20: =E9*E15 | F20: =F9*F15 | G20: =G9*G15 | H20: =H9*H15 | I20: =I9*I15 | J20: =J9*J15 | ... N20: =N9*N15 | O20: =SUM(C20:N20)
B21: Household Care revenue | C21: =C10*C16 | D21: =D10*D16 | E21: =E10*E16 | F21: =F10*F16 | G21: =G10*G16 | H21: =H10*H16 | I21: =I10*I16 | J21: =J10*J16 | ... N21: =N10*N16 | O21: =SUM(C21:N21)
B22: Personal Care revenue | C22: =C11*C17 | D22: =D11*D17 | E22: =E11*E17 | F22: =F11*F17 | G22: =G11*G17 | H22: =H11*H17 | I22: =I11*I17 | J22: =J11*J17 | ... N22: =N11*N17 | O22: =SUM(C22:N22)
B23: Plan net revenue | C23: =SUM(C19:C22) | D23: =SUM(D19:D22) | E23: =SUM(E19:E22) | F23: =SUM(F19:F22) | G23: =SUM(G19:G22) | H23: =SUM(H19:H22) | I23: =SUM(I19:I22) | J23: =SUM(J19:J22) | ... O23: =SUM(O19:O22)
B24: Plan ASP $/case | C24: =IF(C12=0,0,C23/C12) | D24: =IF(D12=0,0,D23/D12) | E24: =IF(E12=0,0,E23/E12) | F24: =IF(F12=0,0,F23/F12) | G24: =IF(G12=0,0,G23/G12) | H24: =IF(H12=0,0,H23/H12) | I24: =IF(I12=0,0,I23/I12) | J24: =IF(J12=0,0,J23/J12) | ... O24: =IF(O12=0,0,O23/O12)
B25: Plan mix % of volume
B26: RTD Beverages | C26: =IF(C12=0,0,C8/C12) | D26: =IF(D12=0,0,D8/D12) | E26: =IF(E12=0,0,E8/E12) | F26: =IF(F12=0,0,F8/F12) | G26: =IF(G12=0,0,G8/G12) | H26: =IF(H12=0,0,H8/H12) | I26: =IF(I12=0,0,I8/I12) | J26: =IF(J12=0,0,J8/J12) | ... O26: =IF(O12=0,0,O8/O12)
B27: Salty Snacks | C27: =IF(C12=0,0,C9/C12) | D27: =IF(D12=0,0,D9/D12) | E27: =IF(E12=0,0,E9/E12) | F27: =IF(F12=0,0,F9/F12) | G27: =IF(G12=0,0,G9/G12) | H27: =IF(H12=0,0,H9/H12) | I27: =IF(I12=0,0,I9/I12) | J27: =IF(J12=0,0,J9/J12) | ... O27: =IF(O12=0,0,O9/O12)
B28: Household Care | C28: =IF(C12=0,0,C10/C12) | D28: =IF(D12=0,0,D10/D12) | E28: =IF(E12=0,0,E10/E12) | F28: =IF(F12=0,0,F10/F12) | G28: =IF(G12=0,0,G10/G12) | H28: =IF(H12=0,0,H10/H12) | I28: =IF(I12=0,0,I10/I12) | J28: =IF(J12=0,0,J10/J12) | ... O28: =IF(O12=0,0,O10/O12)
B29: Personal Care | C29: =IF(C12=0,0,C11/C12) | D29: =IF(D12=0,0,D11/D12) | E29: =IF(E12=0,0,E11/E12) | F29: =IF(F12=0,0,F11/F12) | G29: =IF(G12=0,0,G11/G12) | H29: =IF(H12=0,0,H11/H12) | I29: =IF(I12=0,0,I11/I12) | J29: =IF(J12=0,0,J11/J12) | ... O29: =IF(O12=0,0,O11/O12)
B31: FORECAST (scenario applied)
C32: Jan-26 | D32: Feb-26 | E32: Mar-26 | F32: Apr-26 | G32: May-26 | H32: Jun-26 | I32: Jul-26 | J32: Aug-26 | K32: Sep-26 | L32: Oct-26 | M32: Nov-26 | N32: Dec-26 | O32: FY26
B33: RTD Beverages volume | C33: ='01_Assumptions'!C65*'01_Assumptions'!$C$7 | D33: ='01_Assumptions'!D65*'01_Assumptions'!$C$7 | E33: ='01_Assumptions'!E65*'01_Assumptions'!$C$7 | F33: ='01_Assumptions'!F65*'01_Assumptions'!$C$7 | G33: ='01_Assumptions'!G65*'01_Assumptions'!$C$7 | H33: ='01_Assumptions'!H65*'01_Assumptions'!$C$7 | I33: ='01_Assumptions'!I65*'01_Assumptions'!$C$7 | J33: ='01_Assumptions'!J65*'01_Assumptions'!$C$7 | ... N33: ='01_Assumptions'!N65*'01_Assumptions'!$C$7 | O33: =SUM(C33:N33)
B34: Salty Snacks volume | C34: ='01_Assumptions'!C66*'01_Assumptions'!$C$7 | D34: ='01_Assumptions'!D66*'01_Assumptions'!$C$7 | E34: ='01_Assumptions'!E66*'01_Assumptions'!$C$7 | F34: ='01_Assumptions'!F66*'01_Assumptions'!$C$7 | G34: ='01_Assumptions'!G66*'01_Assumptions'!$C$7 | H34: ='01_Assumptions'!H66*'01_Assumptions'!$C$7 | I34: ='01_Assumptions'!I66*'01_Assumptions'!$C$7 | J34: ='01_Assumptions'!J66*'01_Assumptions'!$C$7 | ... N34: ='01_Assumptions'!N66*'01_Assumptions'!$C$7 | O34: =SUM(C34:N34)
B35: Household Care volume | C35: ='01_Assumptions'!C67*'01_Assumptions'!$C$7 | D35: ='01_Assumptions'!D67*'01_Assumptions'!$C$7 | E35: ='01_Assumptions'!E67*'01_Assumptions'!$C$7 | F35: ='01_Assumptions'!F67*'01_Assumptions'!$C$7 | G35: ='01_Assumptions'!G67*'01_Assumptions'!$C$7 | H35: ='01_Assumptions'!H67*'01_Assumptions'!$C$7 | I35: ='01_Assumptions'!I67*'01_Assumptions'!$C$7 | J35: ='01_Assumptions'!J67*'01_Assumptions'!$C$7 | ... N35: ='01_Assumptions'!N67*'01_Assumptions'!$C$7 | O35: =SUM(C35:N35)
B36: Personal Care volume | C36: ='01_Assumptions'!C68*'01_Assumptions'!$C$7 | D36: ='01_Assumptions'!D68*'01_Assumptions'!$C$7 | E36: ='01_Assumptions'!E68*'01_Assumptions'!$C$7 | F36: ='01_Assumptions'!F68*'01_Assumptions'!$C$7 | G36: ='01_Assumptions'!G68*'01_Assumptions'!$C$7 | H36: ='01_Assumptions'!H68*'01_Assumptions'!$C$7 | I36: ='01_Assumptions'!I68*'01_Assumptions'!$C$7 | J36: ='01_Assumptions'!J68*'01_Assumptions'!$C$7 | ... N36: ='01_Assumptions'!N68*'01_Assumptions'!$C$7 | O36: =SUM(C36:N36)
B37: Forecast total volume | C37: =SUM(C33:C36) | D37: =SUM(D33:D36) | E37: =SUM(E33:E36) | F37: =SUM(F33:F36) | G37: =SUM(G33:G36) | H37: =SUM(H33:H36) | I37: =SUM(I33:I36) | J37: =SUM(J33:J36) | ... O37: =SUM(O33:O36)
B39: RTD Beverages net $/case | C39: ='01_Assumptions'!$D$26*'01_Assumptions'!$C$8 | D39: ='01_Assumptions'!$D$26*'01_Assumptions'!$C$8 | E39: ='01_Assumptions'!$D$26*'01_Assumptions'!$C$8 | F39: ='01_Assumptions'!$D$26*'01_Assumptions'!$C$8 | G39: ='01_Assumptions'!$D$26*'01_Assumptions'!$C$8 | H39: ='01_Assumptions'!$D$26*'01_Assumptions'!$C$8 | I39: ='01_Assumptions'!$D$26*'01_Assumptions'!$C$8 | J39: ='01_Assumptions'!$D$26*'01_Assumptions'!$C$8 | ... N39: ='01_Assumptions'!$D$26*'01_Assumptions'!$C$8 | O39: =AVERAGE(C39:N39)
B40: Salty Snacks net $/case | C40: ='01_Assumptions'!$D$27*'01_Assumptions'!$C$8 | D40: ='01_Assumptions'!$D$27*'01_Assumptions'!$C$8 | E40: ='01_Assumptions'!$D$27*'01_Assumptions'!$C$8 | F40: ='01_Assumptions'!$D$27*'01_Assumptions'!$C$8 | G40: ='01_Assumptions'!$D$27*'01_Assumptions'!$C$8 | H40: ='01_Assumptions'!$D$27*'01_Assumptions'!$C$8 | I40: ='01_Assumptions'!$D$27*'01_Assumptions'!$C$8 | J40: ='01_Assumptions'!$D$27*'01_Assumptions'!$C$8 | ... N40: ='01_Assumptions'!$D$27*'01_Assumptions'!$C$8 | O40: =AVERAGE(C40:N40)
B41: Household Care net $/case | C41: ='01_Assumptions'!$D$28*'01_Assumptions'!$C$8 | D41: ='01_Assumptions'!$D$28*'01_Assumptions'!$C$8 | E41: ='01_Assumptions'!$D$28*'01_Assumptions'!$C$8 | F41: ='01_Assumptions'!$D$28*'01_Assumptions'!$C$8 | G41: ='01_Assumptions'!$D$28*'01_Assumptions'!$C$8 | H41: ='01_Assumptions'!$D$28*'01_Assumptions'!$C$8 | I41: ='01_Assumptions'!$D$28*'01_Assumptions'!$C$8 | J41: ='01_Assumptions'!$D$28*'01_Assumptions'!$C$8 | ... N41: ='01_Assumptions'!$D$28*'01_Assumptions'!$C$8 | O41: =AVERAGE(C41:N41)
B42: Personal Care net $/case | C42: ='01_Assumptions'!$D$29*'01_Assumptions'!$C$8 | D42: ='01_Assumptions'!$D$29*'01_Assumptions'!$C$8 | E42: ='01_Assumptions'!$D$29*'01_Assumptions'!$C$8 | F42: ='01_Assumptions'!$D$29*'01_Assumptions'!$C$8 | G42: ='01_Assumptions'!$D$29*'01_Assumptions'!$C$8 | H42: ='01_Assumptions'!$D$29*'01_Assumptions'!$C$8 | I42: ='01_Assumptions'!$D$29*'01_Assumptions'!$C$8 | J42: ='01_Assumptions'!$D$29*'01_Assumptions'!$C$8 | ... N42: ='01_Assumptions'!$D$29*'01_Assumptions'!$C$8 | O42: =AVERAGE(C42:N42)
B44: RTD Beverages revenue | C44: =C33*C39 | D44: =D33*D39 | E44: =E33*E39 | F44: =F33*F39 | G44: =G33*G39 | H44: =H33*H39 | I44: =I33*I39 | J44: =J33*J39 | ... N44: =N33*N39 | O44: =SUM(C44:N44)
B45: Salty Snacks revenue | C45: =C34*C40 | D45: =D34*D40 | E45: =E34*E40 | F45: =F34*F40 | G45: =G34*G40 | H45: =H34*H40 | I45: =I34*I40 | J45: =J34*J40 | ... N45: =N34*N40 | O45: =SUM(C45:N45)
B46: Household Care revenue | C46: =C35*C41 | D46: =D35*D41 | E46: =E35*E41 | F46: =F35*F41 | G46: =G35*G41 | H46: =H35*H41 | I46: =I35*I41 | J46: =J35*J41 | ... N46: =N35*N41 | O46: =SUM(C46:N46)
B47: Personal Care revenue | C47: =C36*C42 | D47: =D36*D42 | E47: =E36*E42 | F47: =F36*F42 | G47: =G36*G42 | H47: =H36*H42 | I47: =I36*I42 | J47: =J36*J42 | ... N47: =N36*N42 | O47: =SUM(C47:N47)
...

Sheet 03_COGS_Build
B2: COGS build — volume × cost per unit
B3: Plan CPU = material + labor + overhead. Forecast CPU = plan CPU × (1 + inflation) × unit-cost factor.
B4: Scenario | C4: ='01_Assumptions'!D6
B6: PLAN
C7: Jan-26 | D7: Feb-26 | E7: Mar-26 | F7: Apr-26 | G7: May-26 | H7: Jun-26 | I7: Jul-26 | J7: Aug-26 | K7: Sep-26 | L7: Oct-26 | M7: Nov-26 | N7: Dec-26 | O7: FY26
B8: RTD Beverages CPU | C8: ='01_Assumptions'!$H$26 | D8: ='01_Assumptions'!$H$26 | E8: ='01_Assumptions'!$H$26 | F8: ='01_Assumptions'!$H$26 | G8: ='01_Assumptions'!$H$26 | H8: ='01_Assumptions'!$H$26 | I8: ='01_Assumptions'!$H$26 | J8: ='01_Assumptions'!$H$26 | ... N8: ='01_Assumptions'!$H$26 | O8: =AVERAGE(C8:N8)
B9: Salty Snacks CPU | C9: ='01_Assumptions'!$H$27 | D9: ='01_Assumptions'!$H$27 | E9: ='01_Assumptions'!$H$27 | F9: ='01_Assumptions'!$H$27 | G9: ='01_Assumptions'!$H$27 | H9: ='01_Assumptions'!$H$27 | I9: ='01_Assumptions'!$H$27 | J9: ='01_Assumptions'!$H$27 | ... N9: ='01_Assumptions'!$H$27 | O9: =AVERAGE(C9:N9)
B10: Household Care CPU | C10: ='01_Assumptions'!$H$28 | D10: ='01_Assumptions'!$H$28 | E10: ='01_Assumptions'!$H$28 | F10: ='01_Assumptions'!$H$28 | G10: ='01_Assumptions'!$H$28 | H10: ='01_Assumptions'!$H$28 | I10: ='01_Assumptions'!$H$28 | J10: ='01_Assumptions'!$H$28 | ... N10: ='01_Assumptions'!$H$28 | O10: =AVERAGE(C10:N10)
B11: Personal Care CPU | C11: ='01_Assumptions'!$H$29 | D11: ='01_Assumptions'!$H$29 | E11: ='01_Assumptions'!$H$29 | F11: ='01_Assumptions'!$H$29 | G11: ='01_Assumptions'!$H$29 | H11: ='01_Assumptions'!$H$29 | I11: ='01_Assumptions'!$H$29 | J11: ='01_Assumptions'!$H$29 | ... N11: ='01_Assumptions'!$H$29 | O11: =AVERAGE(C11:N11)
B13: RTD Beverages COGS | C13: ='02_Revenue_Build'!C8*C8 | D13: ='02_Revenue_Build'!D8*D8 | E13: ='02_Revenue_Build'!E8*E8 | F13: ='02_Revenue_Build'!F8*F8 | G13: ='02_Revenue_Build'!G8*G8 | H13: ='02_Revenue_Build'!H8*H8 | I13: ='02_Revenue_Build'!I8*I8 | J13: ='02_Revenue_Build'!J8*J8 | ... N13: ='02_Revenue_Build'!N8*N8 | O13: =SUM(C13:N13)
B14: Salty Snacks COGS | C14: ='02_Revenue_Build'!C9*C9 | D14: ='02_Revenue_Build'!D9*D9 | E14: ='02_Revenue_Build'!E9*E9 | F14: ='02_Revenue_Build'!F9*F9 | G14: ='02_Revenue_Build'!G9*G9 | H14: ='02_Revenue_Build'!H9*H9 | I14: ='02_Revenue_Build'!I9*I9 | J14: ='02_Revenue_Build'!J9*J9 | ... N14: ='02_Revenue_Build'!N9*N9 | O14: =SUM(C14:N14)
B15: Household Care COGS | C15: ='02_Revenue_Build'!C10*C10 | D15: ='02_Revenue_Build'!D10*D10 | E15: ='02_Revenue_Build'!E10*E10 | F15: ='02_Revenue_Build'!F10*F10 | G15: ='02_Revenue_Build'!G10*G10 | H15: ='02_Revenue_Build'!H10*H10 | I15: ='02_Revenue_Build'!I10*I10 | J15: ='02_Revenue_Build'!J10*J10 | ... N15: ='02_Revenue_Build'!N10*N10 | O15: =SUM(C15:N15)
B16: Personal Care COGS | C16: ='02_Revenue_Build'!C11*C11 | D16: ='02_Revenue_Build'!D11*D11 | E16: ='02_Revenue_Build'!E11*E11 | F16: ='02_Revenue_Build'!F11*F11 | G16: ='02_Revenue_Build'!G11*G11 | H16: ='02_Revenue_Build'!H11*H11 | I16: ='02_Revenue_Build'!I11*I11 | J16: ='02_Revenue_Build'!J11*J11 | ... N16: ='02_Revenue_Build'!N11*N11 | O16: =SUM(C16:N16)
B17: Plan COGS | C17: =SUM(C13:C16) | D17: =SUM(D13:D16) | E17: =SUM(E13:E16) | F17: =SUM(F13:F16) | G17: =SUM(G13:G16) | H17: =SUM(H13:H16) | I17: =SUM(I13:I16) | J17: =SUM(J13:J16) | ... O17: =SUM(O13:O16)
B18: Plan gross profit | C18: ='02_Revenue_Build'!C23-C17 | D18: ='02_Revenue_Build'!D23-D17 | E18: ='02_Revenue_Build'!E23-E17 | F18: ='02_Revenue_Build'!F23-F17 | G18: ='02_Revenue_Build'!G23-G17 | H18: ='02_Revenue_Build'!H23-H17 | I18: ='02_Revenue_Build'!I23-I17 | J18: ='02_Revenue_Build'!J23-J17 | ... O18: ='02_Revenue_Build'!O23-O17
B19: Plan gross margin % | C19: =IF('02_Revenue_Build'!C23=0,0,C18/'02_Revenue_Build'!C23) | D19: =IF('02_Revenue_Build'!D23=0,0,D18/'02_Revenue_Build'!D23) | E19: =IF('02_Revenue_Build'!E23=0,0,E18/'02_Revenue_Build'!E23) | F19: =IF('02_Revenue_Build'!F23=0,0,F18/'02_Revenue_Build'!F23) | G19: =IF('02_Revenue_Build'!G23=0,0,G18/'02_Revenue_Build'!G23) | H19: =IF('02_Revenue_Build'!H23=0,0,H18/'02_Revenue_Build'!H23) | I19: =IF('02_Revenue_Build'!I23=0,0,I18/'02_Revenue_Build'!I23) | J19: =IF('02_Revenue_Build'!J23=0,0,J18/'02_Revenue_Build'!J23) | ... O19: =IF('02_Revenue_Build'!O23=0,0,O18/'02_Revenue_Build'!O23)
B21: FORECAST (scenario applied)
C22: Jan-26 | D22: Feb-26 | E22: Mar-26 | F22: Apr-26 | G22: May-26 | H22: Jun-26 | I22: Jul-26 | J22: Aug-26 | K22: Sep-26 | L22: Oct-26 | M22: Nov-26 | N22: Dec-26 | O22: FY26
B23: RTD Beverages CPU | C23: ='01_Assumptions'!$I$26 | D23: ='01_Assumptions'!$I$26 | E23: ='01_Assumptions'!$I$26 | F23: ='01_Assumptions'!$I$26 | G23: ='01_Assumptions'!$I$26 | H23: ='01_Assumptions'!$I$26 | I23: ='01_Assumptions'!$I$26 | J23: ='01_Assumptions'!$I$26 | ... N23: ='01_Assumptions'!$I$26 | O23: =AVERAGE(C23:N23)
B24: Salty Snacks CPU | C24: ='01_Assumptions'!$I$27 | D24: ='01_Assumptions'!$I$27 | E24: ='01_Assumptions'!$I$27 | F24: ='01_Assumptions'!$I$27 | G24: ='01_Assumptions'!$I$27 | H24: ='01_Assumptions'!$I$27 | I24: ='01_Assumptions'!$I$27 | J24: ='01_Assumptions'!$I$27 | ... N24: ='01_Assumptions'!$I$27 | O24: =AVERAGE(C24:N24)
B25: Household Care CPU | C25: ='01_Assumptions'!$I$28 | D25: ='01_Assumptions'!$I$28 | E25: ='01_Assumptions'!$I$28 | F25: ='01_Assumptions'!$I$28 | G25: ='01_Assumptions'!$I$28 | H25: ='01_Assumptions'!$I$28 | I25: ='01_Assumptions'!$I$28 | J25: ='01_Assumptions'!$I$28 | ... N25: ='01_Assumptions'!$I$28 | O25: =AVERAGE(C25:N25)
B26: Personal Care CPU | C26: ='01_Assumptions'!$I$29 | D26: ='01_Assumptions'!$I$29 | E26: ='01_Assumptions'!$I$29 | F26: ='01_Assumptions'!$I$29 | G26: ='01_Assumptions'!$I$29 | H26: ='01_Assumptions'!$I$29 | I26: ='01_Assumptions'!$I$29 | J26: ='01_Assumptions'!$I$29 | ... N26: ='01_Assumptions'!$I$29 | O26: =AVERAGE(C26:N26)
B28: RTD Beverages COGS | C28: ='02_Revenue_Build'!C33*C23 | D28: ='02_Revenue_Build'!D33*D23 | E28: ='02_Revenue_Build'!E33*E23 | F28: ='02_Revenue_Build'!F33*F23 | G28: ='02_Revenue_Build'!G33*G23 | H28: ='02_Revenue_Build'!H33*H23 | I28: ='02_Revenue_Build'!I33*I23 | J28: ='02_Revenue_Build'!J33*J23 | ... N28: ='02_Revenue_Build'!N33*N23 | O28: =SUM(C28:N28)
B29: Salty Snacks COGS | C29: ='02_Revenue_Build'!C34*C24 | D29: ='02_Revenue_Build'!D34*D24 | E29: ='02_Revenue_Build'!E34*E24 | F29: ='02_Revenue_Build'!F34*F24 | G29: ='02_Revenue_Build'!G34*G24 | H29: ='02_Revenue_Build'!H34*H24 | I29: ='02_Revenue_Build'!I34*I24 | J29: ='02_Revenue_Build'!J34*J24 | ... N29: ='02_Revenue_Build'!N34*N24 | O29: =SUM(C29:N29)
B30: Household Care COGS | C30: ='02_Revenue_Build'!C35*C25 | D30: ='02_Revenue_Build'!D35*D25 | E30: ='02_Revenue_Build'!E35*E25 | F30: ='02_Revenue_Build'!F35*F25 | G30: ='02_Revenue_Build'!G35*G25 | H30: ='02_Revenue_Build'!H35*H25 | I30: ='02_Revenue_Build'!I35*I25 | J30: ='02_Revenue_Build'!J35*J25 | ... N30: ='02_Revenue_Build'!N35*N25 | O30: =SUM(C30:N30)
B31: Personal Care COGS | C31: ='02_Revenue_Build'!C36*C26 | D31: ='02_Revenue_Build'!D36*D26 | E31: ='02_Revenue_Build'!E36*E26 | F31: ='02_Revenue_Build'!F36*F26 | G31: ='02_Revenue_Build'!G36*G26 | H31: ='02_Revenue_Build'!H36*H26 | I31: ='02_Revenue_Build'!I36*I26 | J31: ='02_Revenue_Build'!J36*J26 | ... N31: ='02_Revenue_Build'!N36*N26 | O31: =SUM(C31:N31)
B32: Forecast COGS | C32: =SUM(C28:C31) | D32: =SUM(D28:D31) | E32: =SUM(E28:E31) | F32: =SUM(F28:F31) | G32: =SUM(G28:G31) | H32: =SUM(H28:H31) | I32: =SUM(I28:I31) | J32: =SUM(J28:J31) | ... O32: =SUM(O28:O31)
B33: Forecast gross profit | C33: ='02_Revenue_Build'!C48-C32 | D33: ='02_Revenue_Build'!D48-D32 | E33: ='02_Revenue_Build'!E48-E32 | F33: ='02_Revenue_Build'!F48-F32 | G33: ='02_Revenue_Build'!G48-G32 | H33: ='02_Revenue_Build'!H48-H32 | I33: ='02_Revenue_Build'!I48-I32 | J33: ='02_Revenue_Build'!J48-J32 | ... O33: ='02_Revenue_Build'!O48-O32
B34: Forecast gross margin % | C34: =IF('02_Revenue_Build'!C48=0,0,C33/'02_Revenue_Build'!C48) | D34: =IF('02_Revenue_Build'!D48=0,0,D33/'02_Revenue_Build'!D48) | E34: =IF('02_Revenue_Build'!E48=0,0,E33/'02_Revenue_Build'!E48) | F34: =IF('02_Revenue_Build'!F48=0,0,F33/'02_Revenue_Build'!F48) | G34: =IF('02_Revenue_Build'!G48=0,0,G33/'02_Revenue_Build'!G48) | H34: =IF('02_Revenue_Build'!H48=0,0,H33/'02_Revenue_Build'!H48) | I34: =IF('02_Revenue_Build'!I48=0,0,I33/'02_Revenue_Build'!I48) | J34: =IF('02_Revenue_Build'!J48=0,0,J33/'02_Revenue_Build'!J48) | ... O34: =IF('02_Revenue_Build'!O48=0,0,O33/'02_Revenue_Build'!O48)
B36: VARIANCE (forecast − plan)
C37: Jan-26 | D37: Feb-26 | E37: Mar-26 | F37: Apr-26 | G37: May-26 | H37: Jun-26 | I37: Jul-26 | J37: Aug-26 | K37: Sep-26 | L37: Oct-26 | M37: Nov-26 | N37: Dec-26 | O37: FY26
B38: COGS var | C38: =C32-C17 | D38: =D32-D17 | E38: =E32-E17 | F38: =F32-F17 | G38: =G32-G17 | H38: =H32-H17 | I38: =I32-I17 | J38: =J32-J17 | ... O38: =O32-O17
B39: Gross profit var | C39: =C33-C18 | D39: =D33-D18 | E39: =E33-E18 | F39: =F33-F18 | G39: =G33-G18 | H39: =H33-H18 | I39: =I33-I18 | J39: =J33-J18 | ... O39: =O33-O18
B40: Gross margin pts | C40: =C34-C19 | D40: =D34-D19 | E40: =E34-E19 | F40: =F34-F19 | G40: =G34-G19 | H40: =H34-H19 | I40: =I34-I19 | J40: =J34-J19 | ... O40: =O34-O19
B42: CPU is $ per case. COGS $000s = 000 cases × $ per case. Inflation and the scenario unit-cost factor both sit in forecast CPU on Assumptions (column I).

Sheet 04_OpEx
B2: OpEx by cost center
B3: Selling and marketing = % of sales + monthly fixed. Distribution = $ per case + monthly fixed. G&A and R&D are monthly fixed. Discretionary factor scales forecast marketing + R&D fixed.
B4: Scenario | C4: ='01_Assumptions'!D6
B6: PLAN
C7: Jan-26 | D7: Feb-26 | E7: Mar-26 | F7: Apr-26 | G7: May-26 | H7: Jun-26 | I7: Jul-26 | J7: Aug-26 | K7: Sep-26 | L7: Oct-26 | M7: Nov-26 | N7: Dec-26 | O7: FY26
B8: Selling | C8: ='01_Assumptions'!$C$33*'02_Revenue_Build'!C23+'01_Assumptions'!C39 | D8: ='01_Assumptions'!$C$33*'02_Revenue_Build'!D23+'01_Assumptions'!D39 | E8: ='01_Assumptions'!$C$33*'02_Revenue_Build'!E23+'01_Assumptions'!E39 | F8: ='01_Assumptions'!$C$33*'02_Revenue_Build'!F23+'01_Assumptions'!F39 | G8: ='01_Assumptions'!$C$33*'02_Revenue_Build'!G23+'01_Assumptions'!G39 | H8: ='01_Assumptions'!$C$33*'02_Revenue_Build'!H23+'01_Assumptions'!H39 | I8: ='01_Assumptions'!$C$33*'02_Revenue_Build'!I23+'01_Assumptions'!I39 | J8: ='01_Assumptions'!$C$33*'02_Revenue_Build'!J23+'01_Assumptions'!J39 | ... N8: ='01_Assumptions'!$C$33*'02_Revenue_Build'!N23+'01_Assumptions'!N39 | O8: =SUM(C8:N8)
B9: Marketing | C9: ='01_Assumptions'!$C$34*'02_Revenue_Build'!C23+'01_Assumptions'!C40 | D9: ='01_Assumptions'!$C$34*'02_Revenue_Build'!D23+'01_Assumptions'!D40 | E9: ='01_Assumptions'!$C$34*'02_Revenue_Build'!E23+'01_Assumptions'!E40 | F9: ='01_Assumptions'!$C$34*'02_Revenue_Build'!F23+'01_Assumptions'!F40 | G9: ='01_Assumptions'!$C$34*'02_Revenue_Build'!G23+'01_Assumptions'!G40 | H9: ='01_Assumptions'!$C$34*'02_Revenue_Build'!H23+'01_Assumptions'!H40 | I9: ='01_Assumptions'!$C$34*'02_Revenue_Build'!I23+'01_Assumptions'!I40 | J9: ='01_Assumptions'!$C$34*'02_Revenue_Build'!J23+'01_Assumptions'!J40 | ... N9: ='01_Assumptions'!$C$34*'02_Revenue_Build'!N23+'01_Assumptions'!N40 | O9: =SUM(C9:N9)
B10: Distribution | C10: ='01_Assumptions'!$C$35*'02_Revenue_Build'!C12+'01_Assumptions'!C41 | D10: ='01_Assumptions'!$C$35*'02_Revenue_Build'!D12+'01_Assumptions'!D41 | E10: ='01_Assumptions'!$C$35*'02_Revenue_Build'!E12+'01_Assumptions'!E41 | F10: ='01_Assumptions'!$C$35*'02_Revenue_Build'!F12+'01_Assumptions'!F41 | G10: ='01_Assumptions'!$C$35*'02_Revenue_Build'!G12+'01_Assumptions'!G41 | H10: ='01_Assumptions'!$C$35*'02_Revenue_Build'!H12+'01_Assumptions'!H41 | I10: ='01_Assumptions'!$C$35*'02_Revenue_Build'!I12+'01_Assumptions'!I41 | J10: ='01_Assumptions'!$C$35*'02_Revenue_Build'!J12+'01_Assumptions'!J41 | ... N10: ='01_Assumptions'!$C$35*'02_Revenue_Build'!N12+'01_Assumptions'!N41 | O10: =SUM(C10:N10)
B11: G&A | C11: ='01_Assumptions'!C42 | D11: ='01_Assumptions'!D42 | E11: ='01_Assumptions'!E42 | F11: ='01_Assumptions'!F42 | G11: ='01_Assumptions'!G42 | H11: ='01_Assumptions'!H42 | I11: ='01_Assumptions'!I42 | J11: ='01_Assumptions'!J42 | ... N11: ='01_Assumptions'!N42 | O11: =SUM(C11:N11)
B12: R&D | C12: ='01_Assumptions'!C43 | D12: ='01_Assumptions'!D43 | E12: ='01_Assumptions'!E43 | F12: ='01_Assumptions'!F43 | G12: ='01_Assumptions'!G43 | H12: ='01_Assumptions'!H43 | I12: ='01_Assumptions'!I43 | J12: ='01_Assumptions'!J43 | ... N12: ='01_Assumptions'!N43 | O12: =SUM(C12:N12)
B13: Plan total OpEx | C13: =SUM(C8:C12) | D13: =SUM(D8:D12) | E13: =SUM(E8:E12) | F13: =SUM(F8:F12) | G13: =SUM(G8:G12) | H13: =SUM(H8:H12) | I13: =SUM(I8:I12) | J13: =SUM(J8:J12) | ... O13: =SUM(O8:O12)
B14: Plan OpEx % of sales | C14: =IF('02_Revenue_Build'!C23=0,0,C13/'02_Revenue_Build'!C23) | D14: =IF('02_Revenue_Build'!D23=0,0,D13/'02_Revenue_Build'!D23) | E14: =IF('02_Revenue_Build'!E23=0,0,E13/'02_Revenue_Build'!E23) | F14: =IF('02_Revenue_Build'!F23=0,0,F13/'02_Revenue_Build'!F23) | G14: =IF('02_Revenue_Build'!G23=0,0,G13/'02_Revenue_Build'!G23) | H14: =IF('02_Revenue_Build'!H23=0,0,H13/'02_Revenue_Build'!H23) | I14: =IF('02_Revenue_Build'!I23=0,0,I13/'02_Revenue_Build'!I23) | J14: =IF('02_Revenue_Build'!J23=0,0,J13/'02_Revenue_Build'!J23) | ... O14: =IF('02_Revenue_Build'!O23=0,0,O13/'02_Revenue_Build'!O23)
B16: FORECAST (scenario applied)
C17: Jan-26 | D17: Feb-26 | E17: Mar-26 | F17: Apr-26 | G17: May-26 | H17: Jun-26 | I17: Jul-26 | J17: Aug-26 | K17: Sep-26 | L17: Oct-26 | M17: Nov-26 | N17: Dec-26 | O17: FY26
B18: Selling | C18: ='01_Assumptions'!$D$33*'02_Revenue_Build'!C48+'01_Assumptions'!C48 | D18: ='01_Assumptions'!$D$33*'02_Revenue_Build'!D48+'01_Assumptions'!D48 | E18: ='01_Assumptions'!$D$33*'02_Revenue_Build'!E48+'01_Assumptions'!E48 | F18: ='01_Assumptions'!$D$33*'02_Revenue_Build'!F48+'01_Assumptions'!F48 | G18: ='01_Assumptions'!$D$33*'02_Revenue_Build'!G48+'01_Assumptions'!G48 | H18: ='01_Assumptions'!$D$33*'02_Revenue_Build'!H48+'01_Assumptions'!H48 | I18: ='01_Assumptions'!$D$33*'02_Revenue_Build'!I48+'01_Assumptions'!I48 | J18: ='01_Assumptions'!$D$33*'02_Revenue_Build'!J48+'01_Assumptions'!J48 | ... N18: ='01_Assumptions'!$D$33*'02_Revenue_Build'!N48+'01_Assumptions'!N48 | O18: =SUM(C18:N18)
B19: Marketing | C19: ='01_Assumptions'!$D$34*'02_Revenue_Build'!C48+'01_Assumptions'!C49*'01_Assumptions'!$C$10 | D19: ='01_Assumptions'!$D$34*'02_Revenue_Build'!D48+'01_Assumptions'!D49*'01_Assumptions'!$C$10 | E19: ='01_Assumptions'!$D$34*'02_Revenue_Build'!E48+'01_Assumptions'!E49*'01_Assumptions'!$C$10 | F19: ='01_Assumptions'!$D$34*'02_Revenue_Build'!F48+'01_Assumptions'!F49*'01_Assumptions'!$C$10 | G19: ='01_Assumptions'!$D$34*'02_Revenue_Build'!G48+'01_Assumptions'!G49*'01_Assumptions'!$C$10 | H19: ='01_Assumptions'!$D$34*'02_Revenue_Build'!H48+'01_Assumptions'!H49*'01_Assumptions'!$C$10 | I19: ='01_Assumptions'!$D$34*'02_Revenue_Build'!I48+'01_Assumptions'!I49*'01_Assumptions'!$C$10 | J19: ='01_Assumptions'!$D$34*'02_Revenue_Build'!J48+'01_Assumptions'!J49*'01_Assumptions'!$C$10 | ... N19: ='01_Assumptions'!$D$34*'02_Revenue_Build'!N48+'01_Assumptions'!N49*'01_Assumptions'!$C$10 | O19: =SUM(C19:N19)
B20: Distribution | C20: ='01_Assumptions'!$D$35*'02_Revenue_Build'!C37+'01_Assumptions'!C50 | D20: ='01_Assumptions'!$D$35*'02_Revenue_Build'!D37+'01_Assumptions'!D50 | E20: ='01_Assumptions'!$D$35*'02_Revenue_Build'!E37+'01_Assumptions'!E50 | F20: ='01_Assumptions'!$D$35*'02_Revenue_Build'!F37+'01_Assumptions'!F50 | G20: ='01_Assumptions'!$D$35*'02_Revenue_Build'!G37+'01_Assumptions'!G50 | H20: ='01_Assumptions'!$D$35*'02_Revenue_Build'!H37+'01_Assumptions'!H50 | I20: ='01_Assumptions'!$D$35*'02_Revenue_Build'!I37+'01_Assumptions'!I50 | J20: ='01_Assumptions'!$D$35*'02_Revenue_Build'!J37+'01_Assumptions'!J50 | ... N20: ='01_Assumptions'!$D$35*'02_Revenue_Build'!N37+'01_Assumptions'!N50 | O20: =SUM(C20:N20)
B21: G&A | C21: ='01_Assumptions'!C51 | D21: ='01_Assumptions'!D51 | E21: ='01_Assumptions'!E51 | F21: ='01_Assumptions'!F51 | G21: ='01_Assumptions'!G51 | H21: ='01_Assumptions'!H51 | I21: ='01_Assumptions'!I51 | J21: ='01_Assumptions'!J51 | ... N21: ='01_Assumptions'!N51 | O21: =SUM(C21:N21)
B22: R&D | C22: ='01_Assumptions'!C52*'01_Assumptions'!$C$10 | D22: ='01_Assumptions'!D52*'01_Assumptions'!$C$10 | E22: ='01_Assumptions'!E52*'01_Assumptions'!$C$10 | F22: ='01_Assumptions'!F52*'01_Assumptions'!$C$10 | G22: ='01_Assumptions'!G52*'01_Assumptions'!$C$10 | H22: ='01_Assumptions'!H52*'01_Assumptions'!$C$10 | I22: ='01_Assumptions'!I52*'01_Assumptions'!$C$10 | J22: ='01_Assumptions'!J52*'01_Assumptions'!$C$10 | ... N22: ='01_Assumptions'!N52*'01_Assumptions'!$C$10 | O22: =SUM(C22:N22)
B23: Forecast total OpEx | C23: =SUM(C18:C22) | D23: =SUM(D18:D22) | E23: =SUM(E18:E22) | F23: =SUM(F18:F22) | G23: =SUM(G18:G22) | H23: =SUM(H18:H22) | I23: =SUM(I18:I22) | J23: =SUM(J18:J22) | ... O23: =SUM(O18:O22)
B24: Forecast OpEx % of sales | C24: =IF('02_Revenue_Build'!C48=0,0,C23/'02_Revenue_Build'!C48) | D24: =IF('02_Revenue_Build'!D48=0,0,D23/'02_Revenue_Build'!D48) | E24: =IF('02_Revenue_Build'!E48=0,0,E23/'02_Revenue_Build'!E48) | F24: =IF('02_Revenue_Build'!F48=0,0,F23/'02_Revenue_Build'!F48) | G24: =IF('02_Revenue_Build'!G48=0,0,G23/'02_Revenue_Build'!G48) | H24: =IF('02_Revenue_Build'!H48=0,0,H23/'02_Revenue_Build'!H48) | I24: =IF('02_Revenue_Build'!I48=0,0,I23/'02_Revenue_Build'!I48) | J24: =IF('02_Revenue_Build'!J48=0,0,J23/'02_Revenue_Build'!J48) | ... O24: =IF('02_Revenue_Build'!O48=0,0,O23/'02_Revenue_Build'!O48)
B26: VARIANCE (forecast − plan)
C27: Jan-26 | D27: Feb-26 | E27: Mar-26 | F27: Apr-26 | G27: May-26 | H27: Jun-26 | I27: Jul-26 | J27: Aug-26 | K27: Sep-26 | L27: Oct-26 | M27: Nov-26 | N27: Dec-26 | O27: FY26
B28: Selling | C28: =C18-C8 | D28: =D18-D8 | E28: =E18-E8 | F28: =F18-F8 | G28: =G18-G8 | H28: =H18-H8 | I28: =I18-I8 | J28: =J18-J8 | ... O28: =O18-O8
B29: Marketing | C29: =C19-C9 | D29: =D19-D9 | E29: =E19-E9 | F29: =F19-F9 | G29: =G19-G9 | H29: =H19-H9 | I29: =I19-I9 | J29: =J19-J9 | ... O29: =O19-O9
B30: Distribution | C30: =C20-C10 | D30: =D20-D10 | E30: =E20-E10 | F30: =F20-F10 | G30: =G20-G10 | H30: =H20-H10 | I30: =I20-I10 | J30: =J20-J10 | ... O30: =O20-O10
B31: G&A | C31: =C21-C11 | D31: =D21-D11 | E31: =E21-E11 | F31: =F21-F11 | G31: =G21-G11 | H31: =H21-H11 | I31: =I21-I11 | J31: =J21-J11 | ... O31: =O21-O11
B32: R&D | C32: =C22-C12 | D32: =D22-D12 | E32: =E22-E12 | F32: =F22-F12 | G32: =G22-G12 | H32: =H22-H12 | I32: =I22-I12 | J32: =J22-J12 | ... O32: =O22-O12
B33: Total OpEx | C33: =C23-C13 | D33: =D23-D13 | E33: =E23-E13 | F33: =F23-F13 | G33: =G23-G13 | H33: =H23-H13 | I33: =I23-I13 | J33: =J23-J13 | ... O33: =O23-O13
B35: Distribution $ per case × 000 cases = $000s. Discretionary factor (Assumptions C10) applies to forecast marketing campaigns and R&D only.

Sheet 05_P&L_Forecast
B2: P&L forecast — 12 months
B3: Main grid is the latest-view forecast (scenario applied). Right-hand columns compare FY forecast vs FY plan.
B4: Scenario | C4: ='01_Assumptions'!D6
B6: Forecast P&L ($000s)
C7: Jan-26 | D7: Feb-26 | E7: Mar-26 | F7: Apr-26 | G7: May-26 | H7: Jun-26 | I7: Jul-26 | J7: Aug-26 | K7: Sep-26 | L7: Oct-26 | M7: Nov-26 | N7: Dec-26 | O7: FY Fcst | P7: FY Plan | Q7: Var | R7: Var %
B8: Net revenue | C8: ='02_Revenue_Build'!C48 | D8: ='02_Revenue_Build'!D48 | E8: ='02_Revenue_Build'!E48 | F8: ='02_Revenue_Build'!F48 | G8: ='02_Revenue_Build'!G48 | H8: ='02_Revenue_Build'!H48 | I8: ='02_Revenue_Build'!I48 | J8: ='02_Revenue_Build'!J48 | ... N8: ='02_Revenue_Build'!N48 | O8: =SUM(C8:N8) | P8: ='02_Revenue_Build'!O23 | Q8: =O8-P8 | R8: =IF(P8=0,0,Q8/P8)
B9: COGS | C9: ='03_COGS_Build'!C32 | D9: ='03_COGS_Build'!D32 | E9: ='03_COGS_Build'!E32 | F9: ='03_COGS_Build'!F32 | G9: ='03_COGS_Build'!G32 | H9: ='03_COGS_Build'!H32 | I9: ='03_COGS_Build'!I32 | J9: ='03_COGS_Build'!J32 | ... N9: ='03_COGS_Build'!N32 | O9: =SUM(C9:N9) | P9: ='03_COGS_Build'!O17 | Q9: =O9-P9 | R9: =IF(P9=0,0,Q9/P9)
B10: Gross profit | C10: =C8-C9 | D10: =D8-D9 | E10: =E8-E9 | F10: =F8-F9 | G10: =G8-G9 | H10: =H8-H9 | I10: =I8-I9 | J10: =J8-J9 | ... N10: =N8-N9 | O10: =SUM(C10:N10) | P10: =P8-P9 | Q10: =O10-P10 | R10: =IF(P10=0,0,Q10/P10)
B11: Gross margin % | C11: =IF(C8=0,0,C10/C8) | D11: =IF(D8=0,0,D10/D8) | E11: =IF(E8=0,0,E10/E8) | F11: =IF(F8=0,0,F10/F8) | G11: =IF(G8=0,0,G10/G8) | H11: =IF(H8=0,0,H10/H8) | I11: =IF(I8=0,0,I10/I8) | J11: =IF(J8=0,0,J10/J8) | ... P11: =IF(P8=0,0,P10/P8) | Q11: =O11-P11 | R11: ="n/a"
B12: Selling | C12: ='04_OpEx'!C18 | D12: ='04_OpEx'!D18 | E12: ='04_OpEx'!E18 | F12: ='04_OpEx'!F18 | G12: ='04_OpEx'!G18 | H12: ='04_OpEx'!H18 | I12: ='04_OpEx'!I18 | J12: ='04_OpEx'!J18 | ... N12: ='04_OpEx'!N18 | O12: =SUM(C12:N12) | P12: ='04_OpEx'!O8 | Q12: =O12-P12 | R12: =IF(P12=0,0,Q12/P12)
B13: Marketing | C13: ='04_OpEx'!C19 | D13: ='04_OpEx'!D19 | E13: ='04_OpEx'!E19 | F13: ='04_OpEx'!F19 | G13: ='04_OpEx'!G19 | H13: ='04_OpEx'!H19 | I13: ='04_OpEx'!I19 | J13: ='04_OpEx'!J19 | ... N13: ='04_OpEx'!N19 | O13: =SUM(C13:N13) | P13: ='04_OpEx'!O9 | Q13: =O13-P13 | R13: =IF(P13=0,0,Q13/P13)
B14: Distribution | C14: ='04_OpEx'!C20 | D14: ='04_OpEx'!D20 | E14: ='04_OpEx'!E20 | F14: ='04_OpEx'!F20 | G14: ='04_OpEx'!G20 | H14: ='04_OpEx'!H20 | I14: ='04_OpEx'!I20 | J14: ='04_OpEx'!J20 | ... N14: ='04_OpEx'!N20 | O14: =SUM(C14:N14) | P14: ='04_OpEx'!O10 | Q14: =O14-P14 | R14: =IF(P14=0,0,Q14/P14)
B15: G&A | C15: ='04_OpEx'!C21 | D15: ='04_OpEx'!D21 | E15: ='04_OpEx'!E21 | F15: ='04_OpEx'!F21 | G15: ='04_OpEx'!G21 | H15: ='04_OpEx'!H21 | I15: ='04_OpEx'!I21 | J15: ='04_OpEx'!J21 | ... N15: ='04_OpEx'!N21 | O15: =SUM(C15:N15) | P15: ='04_OpEx'!O11 | Q15: =O15-P15 | R15: =IF(P15=0,0,Q15/P15)
B16: R&D | C16: ='04_OpEx'!C22 | D16: ='04_OpEx'!D22 | E16: ='04_OpEx'!E22 | F16: ='04_OpEx'!F22 | G16: ='04_OpEx'!G22 | H16: ='04_OpEx'!H22 | I16: ='04_OpEx'!I22 | J16: ='04_OpEx'!J22 | ... N16: ='04_OpEx'!N22 | O16: =SUM(C16:N16) | P16: ='04_OpEx'!O12 | Q16: =O16-P16 | R16: =IF(P16=0,0,Q16/P16)
B17: Total OpEx | C17: ='04_OpEx'!C23 | D17: ='04_OpEx'!D23 | E17: ='04_OpEx'!E23 | F17: ='04_OpEx'!F23 | G17: ='04_OpEx'!G23 | H17: ='04_OpEx'!H23 | I17: ='04_OpEx'!I23 | J17: ='04_OpEx'!J23 | ... N17: ='04_OpEx'!N23 | O17: =SUM(C17:N17) | P17: ='04_OpEx'!O13 | Q17: =O17-P17 | R17: =IF(P17=0,0,Q17/P17)
B18: EBITDA | C18: =C10-C17 | D18: =D10-D17 | E18: =E10-E17 | F18: =F10-F17 | G18: =G10-G17 | H18: =H10-H17 | I18: =I10-I17 | J18: =J10-J17 | ... N18: =N10-N17 | O18: =SUM(C18:N18) | P18: =P10-P17 | Q18: =O18-P18 | R18: =IF(P18=0,0,Q18/P18)
B19: EBITDA % | C19: =IF(C8=0,0,C18/C8) | D19: =IF(D8=0,0,D18/D8) | E19: =IF(E8=0,0,E18/E8) | F19: =IF(F8=0,0,F18/F8) | G19: =IF(G8=0,0,G18/G8) | H19: =IF(H8=0,0,H18/H8) | I19: =IF(I8=0,0,I18/I8) | J19: =IF(J8=0,0,J18/J8) | ... P19: =IF(P8=0,0,P18/P8) | Q19: =O19-P19 | R19: ="n/a"
B20: D&A | C20: ='01_Assumptions'!$C$21*C8 | D20: ='01_Assumptions'!$C$21*D8 | E20: ='01_Assumptions'!$C$21*E8 | F20: ='01_Assumptions'!$C$21*F8 | G20: ='01_Assumptions'!$C$21*G8 | H20: ='01_Assumptions'!$C$21*H8 | I20: ='01_Assumptions'!$C$21*I8 | J20: ='01_Assumptions'!$C$21*J8 | ... N20: ='01_Assumptions'!$C$21*N8 | O20: =SUM(C20:N20) | P20: ='01_Assumptions'!$C$21*P8 | Q20: =O20-P20 | R20: =IF(P20=0,0,Q20/P20)
B21: EBIT | C21: =C18-C20 | D21: =D18-D20 | E21: =E18-E20 | F21: =F18-F20 | G21: =G18-G20 | H21: =H18-H20 | I21: =I18-I20 | J21: =J18-J20 | ... N21: =N18-N20 | O21: =SUM(C21:N21) | P21: =P18-P20 | Q21: =O21-P21 | R21: =IF(P21=0,0,Q21/P21)
B22: Tax | C22: ='01_Assumptions'!$C$20*C21 | D22: ='01_Assumptions'!$C$20*D21 | E22: ='01_Assumptions'!$C$20*E21 | F22: ='01_Assumptions'!$C$20*F21 | G22: ='01_Assumptions'!$C$20*G21 | H22: ='01_Assumptions'!$C$20*H21 | I22: ='01_Assumptions'!$C$20*I21 | J22: ='01_Assumptions'!$C$20*J21 | ... N22: ='01_Assumptions'!$C$20*N21 | O22: =SUM(C22:N22) | P22: ='01_Assumptions'!$C$20*P21 | Q22: =O22-P22 | R22: =IF(P22=0,0,Q22/P22)
B23: Net income | C23: =C21-C22 | D23: =D21-D22 | E23: =E21-E22 | F23: =F21-F22 | G23: =G21-G22 | H23: =H21-H22 | I23: =I21-I22 | J23: =J21-J22 | ... N23: =N21-N22 | O23: =SUM(C23:N23) | P23: =P21-P22 | Q23: =O23-P23 | R23: =IF(P23=0,0,Q23/P23)
B24: Net income % | C24: =IF(C8=0,0,C23/C8) | D24: =IF(D8=0,0,D23/D8) | E24: =IF(E8=0,0,E23/E8) | F24: =IF(F8=0,0,F23/F8) | G24: =IF(G8=0,0,G23/G8) | H24: =IF(H8=0,0,H23/H8) | I24: =IF(I8=0,0,I23/I8) | J24: =IF(J8=0,0,J23/J8) | ... P24: =IF(P8=0,0,P23/P8) | Q24: =O24-P24 | R24: ="n/a"
B26: Plan P&L ($000s) — for the chart
C27: Jan-26 | D27: Feb-26 | E27: Mar-26 | F27: Apr-26 | G27: May-26 | H27: Jun-26 | I27: Jul-26 | J27: Aug-26 | K27: Sep-26 | L27: Oct-26 | M27: Nov-26 | N27: Dec-26 | O27: FY26
B28: Plan net revenue | C28: ='02_Revenue_Build'!C23 | D28: ='02_Revenue_Build'!D23 | E28: ='02_Revenue_Build'!E23 | F28: ='02_Revenue_Build'!F23 | G28: ='02_Revenue_Build'!G23 | H28: ='02_Revenue_Build'!H23 | I28: ='02_Revenue_Build'!I23 | J28: ='02_Revenue_Build'!J23 | ... N28: ='02_Revenue_Build'!N23 | O28: =SUM(C28:N28)
B29: Plan EBITDA | C29: ='02_Revenue_Build'!C23-'03_COGS_Build'!C17-'04_OpEx'!C13 | D29: ='02_Revenue_Build'!D23-'03_COGS_Build'!D17-'04_OpEx'!D13 | E29: ='02_Revenue_Build'!E23-'03_COGS_Build'!E17-'04_OpEx'!E13 | F29: ='02_Revenue_Build'!F23-'03_COGS_Build'!F17-'04_OpEx'!F13 | G29: ='02_Revenue_Build'!G23-'03_COGS_Build'!G17-'04_OpEx'!G13 | H29: ='02_Revenue_Build'!H23-'03_COGS_Build'!H17-'04_OpEx'!H13 | I29: ='02_Revenue_Build'!I23-'03_COGS_Build'!I17-'04_OpEx'!I13 | J29: ='02_Revenue_Build'!J23-'03_COGS_Build'!J17-'04_OpEx'!J13 | ... N29: ='02_Revenue_Build'!N23-'03_COGS_Build'!N17-'04_OpEx'!N13 | O29: =SUM(C29:N29)
B31: Chart data (hidden-style, used by the line chart) | C31: Jan-26 | D31: Feb-26 | E31: Mar-26 | F31: Apr-26 | G31: May-26 | H31: Jun-26 | I31: Jul-26 | J31: Aug-26 | K31: Sep-26 | L31: Oct-26 | M31: Nov-26 | N31: Dec-26
B32: Forecast revenue | C32: =C8 | D32: =D8 | E32: =E8 | F32: =F8 | G32: =G8 | H32: =H8 | I32: =I8 | J32: =J8 | ... N32: =N8
B33: Plan revenue | C33: =C28 | D33: =D28 | E33: =E28 | F33: =F28 | G33: =G28 | H33: =H28 | I33: =I28 | J33: =J28 | ... N33: =N28
B34: Forecast EBITDA | C34: =C18 | D34: =D18 | E34: =E18 | F34: =F18 | G34: =G18 | H34: =H18 | I34: =I18 | J34: =J18 | ... N34: =N18
B35: Plan EBITDA | C35: =C29 | D35: =D29 | E35: =E29 | F35: =F29 | G35: =G29 | H35: =H29 | I35: =I29 | J35: =J29 | ... N35: =N29
B52: Switch the scenario on Assumptions to watch FY var and the charts move. Green cells on this tab are the conversation numbers.

Sheet 06_Bridge
B2: Plan vs forecast bridge
B3: FY walk: volume (constant mix) + mix + price for revenue; volume + mix + cost/unit for COGS; rate vs volume vs fixed for OpEx; then EBITDA.
B4: Scenario | C4: ='01_Assumptions'!D6
B6: Product helpers (FY)
B7: Product | C7: Plan vol | D7: Fcst vol | E7: Plan $/case | F7: Fcst $/case | G7: Plan CPU | H7: Fcst CPU | I7: Plan rev | J7: Fcst rev | K7: Plan COGS | L7: Fcst COGS | M7: Δvol × plan price | N7: Fcst vol × Δprice
B8: RTD Beverages | C8: ='02_Revenue_Build'!O8 | D8: ='02_Revenue_Build'!O33 | E8: ='01_Assumptions'!C26 | F8: ='02_Revenue_Build'!O39 | G8: ='01_Assumptions'!H26 | H8: ='01_Assumptions'!I26 | I8: ='02_Revenue_Build'!O19 | J8: ='02_Revenue_Build'!O44 | K8: ='03_COGS_Build'!O13 | L8: ='03_COGS_Build'!O28 | M8: =(D8-C8)*E8 | N8: =D8*(F8-E8)
B9: Salty Snacks | C9: ='02_Revenue_Build'!O9 | D9: ='02_Revenue_Build'!O34 | E9: ='01_Assumptions'!C27 | F9: ='02_Revenue_Build'!O40 | G9: ='01_Assumptions'!H27 | H9: ='01_Assumptions'!I27 | I9: ='02_Revenue_Build'!O20 | J9: ='02_Revenue_Build'!O45 | K9: ='03_COGS_Build'!O14 | L9: ='03_COGS_Build'!O29 | M9: =(D9-C9)*E9 | N9: =D9*(F9-E9)
B10: Household Care | C10: ='02_Revenue_Build'!O10 | D10: ='02_Revenue_Build'!O35 | E10: ='01_Assumptions'!C28 | F10: ='02_Revenue_Build'!O41 | G10: ='01_Assumptions'!H28 | H10: ='01_Assumptions'!I28 | I10: ='02_Revenue_Build'!O21 | J10: ='02_Revenue_Build'!O46 | K10: ='03_COGS_Build'!O15 | L10: ='03_COGS_Build'!O30 | M10: =(D10-C10)*E10 | N10: =D10*(F10-E10)
B11: Personal Care | C11: ='02_Revenue_Build'!O11 | D11: ='02_Revenue_Build'!O36 | E11: ='01_Assumptions'!C29 | F11: ='02_Revenue_Build'!O42 | G11: ='01_Assumptions'!H29 | H11: ='01_Assumptions'!I29 | I11: ='02_Revenue_Build'!O22 | J11: ='02_Revenue_Build'!O47 | K11: ='03_COGS_Build'!O16 | L11: ='03_COGS_Build'!O31 | M11: =(D11-C11)*E11 | N11: =D11*(F11-E11)
B12: Total | C12: =SUM(C8:C11) | D12: =SUM(D8:D11) | E12: =IF(C12=0,0,I12/C12) | F12: =IF(D12=0,0,J12/D12) | G12: =IF(C12=0,0,K12/C12) | H12: =IF(D12=0,0,L12/D12) | I12: =SUM(I8:I11) | J12: =SUM(J8:J11) | K12: =SUM(K8:K11) | L12: =SUM(L8:L11) | M12: =SUM(M8:M11) | N12: =SUM(N8:N11)
B14: Revenue walk ($000s)
B15: Step | C15: $000s | D15: Note
B16: Plan revenue | C16: =I12 | D16: Locked annual plan
B17: Volume (constant mix) | C17: =(D12-C12)*E12 | D17: Δ total cases × plan ASP
B18: Mix | C18: =M12-C17 | D18: Product mix vs plan ASP: Σ(Δvol × plan price) − volume-at-ASP
B19: Price | C19: =N12 | D19: Σ forecast vol × Δ net $/case (includes scenario price factor)
B20: Forecast revenue | C20: =C16+C17+C18+C19 | D20: Must equal 02_Revenue_Build FY forecast
B21: Check vs revenue build | C21: =C20-'02_Revenue_Build'!O48 | D21: Should be ~0 (rounding).
B23: COGS walk ($000s)
B24: Step | C24: $000s | D24: Note
B25: Plan COGS | C25: =K12 | D25: Locked annual plan
B26: Volume (constant mix) | C26: =(D12-C12)*G12 | D26: Δ total cases × plan CPU
B27: Mix | C27: =SUMPRODUCT((D8:D11-C8:C11)*G8:G11)-C26 | D27: Product mix vs plan CPU
B28: Cost / unit | C28: =SUMPRODUCT(D8:D11,(H8:H11-G8:G11)) | D28: Inflation + scenario unit-cost factor at forecast volume
B29: Forecast COGS | C29: =C25+C26+C27+C28 | D29: Must equal 03_COGS_Build FY forecast
B30: Check vs COGS build | C30: =C29-'03_COGS_Build'!O32
B32: OpEx walk ($000s)
B33: Step | C33: $000s | D33: Note
B34: Plan OpEx | C34: ='04_OpEx'!O13 | D34: Locked annual plan
B35: Sales-driven (plan rates) | C35: =('02_Revenue_Build'!O48-'02_Revenue_Build'!O23)*('01_Assumptions'!C33+'01_Assumptions'!C34) | D35: Δ revenue × (plan commission + plan marketing %)
B36: Selling / marketing rate | C36: ='02_Revenue_Build'!O48*(('01_Assumptions'!D33-'01_Assumptions'!C33)+('01_Assumptions'!D34-'01_Assumptions'!C34)) | D36: Forecast revenue × Δ rates
B37: Distribution volume | C37: =('02_Revenue_Build'!O37-'02_Revenue_Build'!O12)*'01_Assumptions'!C35 | D37: Δ cases × plan $ per case
B38: Distribution rate | C38: ='02_Revenue_Build'!O37*('01_Assumptions'!D35-'01_Assumptions'!C35) | D38: Forecast cases × Δ $ per case
B39: Fixed & discretionary | C39: ='04_OpEx'!O23-C34-C35-C36-C37-C38 | D39: Monthly fixed, G&A/R&D, marketing campaigns, scenario OpEx factor — plug to forecast
B40: Forecast OpEx | C40: =C34+C35+C36+C37+C38+C39 | D40: Must equal 04_OpEx FY forecast
B41: Check vs OpEx | C41: =C40-'04_OpEx'!O23
B43: EBITDA walk ($000s)
B44: Step | C44: $000s | D44: Note
B45: Plan EBITDA | C45: ='05_P&L_Forecast'!P18 | D45: From 05_P&L_Forecast FY plan
B46: Gross profit — revenue | C46: =C17+C18+C19 | D46: Volume + mix + price (helps EBITDA)
...

Sheet 07_Data_Dictionary
B2: Data dictionary
B3: Field definitions so another analyst can inherit the file.
B5: Field | C5: Tab | D5: Definition
B6: Scenario | C6: 01_Assumptions | D6: 1 Base / 2 Upside / 3 Downside. Indexes the factor table and scales the latest-view forecast only.
B7: Volume / price / unit-cost / disc. OpEx factors | C7: 01_Assumptions | D7: Applied to forecast volume, forecast net $/case, forecast CPU, and forecast marketing + R&D fixed.
B8: Tax rate | C8: 01_Assumptions | D8: Applied to EBIT on the P&L. Sample 25%.
B9: D&A % of sales | C9: 01_Assumptions | D9: Simple D&A driver for the P&L (not an asset rollforward).
B10: Cost inflation | C10: 01_Assumptions | D10: Forecast CPU = plan CPU × (1 + inflation) × unit-cost factor.
B11: Plan net $/case | C11: 01_Assumptions | D11: Yellow input. Net selling price used in the locked plan.
B12: Fcst net $/case | C12: 01_Assumptions | D12: Yellow input. Latest-view price, then × price factor.
B13: Material / labor / overhead $/case | C13: 01_Assumptions | D13: Plan unit-cost stack. Plan CPU = sum of the three.
B14: Selling commission % | C14: 01_Assumptions | D14: Variable selling cost. Plan and forecast rates can differ.
B15: Marketing % of sales | C15: 01_Assumptions | D15: Brand / trade rate on top of monthly campaign dollars.
B16: Distribution $ per case | C16: 01_Assumptions | D16: Freight and warehousing per case, plus a monthly fixed line.
... B30: Units | C30: All | D30: Dollars in $000s. Volume in 000 cases. Prices and CPU in $ per case. Rates in %.
B31: All sample numbers are fictional. Built for a public GitHub portfolio — no employer data.
